Workbook

Sheet Bull Strangle - Option Samurai
A1: Bull Strangle Screener — OptionSamurai Live Data (Excel Formula Add-in) | April 13, 2026 Entry / May 8, 2026 Expiration
A2: Formulas auto-populate from OptionSamurai. Change expiry in B3 to update all rows. Bull Strangle 1.5% rule: Call +1.5% rounded UP, Put −1.5% rounded DOWN. | Week: April 13, 2026 Entry / May 8, 2026 Expiration
A3: Expiration Date: | B3: 2026-05-08 | C3: ← Change date here (YYYY-MM-DD) to update ALL formulas
A4: Stock Info (Live) | F4: MA Filter — 2-of-4 Min (50d / 200d / 1m Perf / 3m Perf) | J4: 1.5% Strangle Strikes | P4: Covered Call | S4: Cash-Secured Put | V4: Earnings | W4: Prob & Quality | AE4: 25Δ Reference | AI4: Prob OTM | AL4: Advisory (Informational) | AQ4: Open P&L ⚠️ Fill on Open
A5: Symbol | B5: Last Price | C5: Stock IV | D5: Sector | E5: Industry | F5: Above MAs (0–4 Count) | G5: MA Detail (all 4) | H5: 1m Perf (20d proxy) | I5: 3m Perf (100d proxy) | J5: 1.5% Call Strike | K5: Call Bid | L5: 1.5% Put Strike | M5: Put Bid | N5: Total Credit | O5: % Return (4-wk) | P5: CC Strike | Q5: CC Bid | R5: CC % | S5: CSP Strike | T5: CSP Bid | U5: CSP % | V5: Next Earnings | W5: Call Delta | X5: Put Delta (abs) | Y5: Prob Profit | Z5: Prob Loss | AA5: Call Dist % | AB5: Put Dist % | AC5: Strike Gap | AD5: TRADE? | AE5: 25Δ Call Strike | AF5: 25Δ Call Bid | AG5: 25Δ Put Strike | AH5: 25Δ Put Bid | AI5: Call Prob Worthless | AJ5: Put Prob Worthless | AK5: Prob Both Worthless | AL5: IV-RV Pctl | AM5: ATR % | AN5: Short Ratio | AO5: IV-RV Flag | AP5: Path Stability | AQ5: Entry Call Bid ⚠️FILL | AR5: Entry Put Bid ⚠️FILL | AS5: Call Intrinsic | AT5: Put Intrinsic | AU5: Open P&L ×100 shs
A6: PSKY | B6: =_xldudf_optionsamurai_stock(A6,"stock_last") -> 11.61 | C6: =_xldudf_optionsamurai_stock(A6,"stock_iv") -> 0.6441 | D6: =_xldudf_optionsamurai_stock(A6,"sector") -> Communication Services | E6: =_xldudf_optionsamurai_stock(A6,"industry") -> Entertainment | F6: =IF(AND(ISNUMBER(_xldudf_optionsamurai_stock(A6,"sma_50d")),ISNUMBER(_xldudf_optionsamurai_stock(A6,"sma_200d")),ISNUMBER(_xldudf_optionsamurai_stock(A6,"perf_m")),ISNUMBER(_xldudf_optionsamurai_stock(A6,"perf_q"))),(_xldudf_optionsamurai_stock(A6,"sma_50d")>0)*1+(_xldudf_optionsamurai_stock(A6,"sma_200d")>0)*1+(_xldudf_optionsamurai_stock(A6,"perf_m")>0)*1+(_xldudf_optionsamurai_stock(A6,"perf_q")>0)*1,"") -> 3 | G6: =IF(ISNUMBER(_xldudf_optionsamurai_stock(A6,"sma_50d")),"50d:"&TEXT(_xldudf_optionsamurai_stock(A6,"sma_50d"),"0.0%")&" 200d:"&TEXT(_xldudf_optionsamurai_stock(A6,"sma_200d"),"0.0%")&" 1m:"&TEXT(_xldudf_optionsamurai_stock(A6,"perf_m"),"0.0%")&" 3m:"&TEXT(_xldudf_optionsamurai_stock(A6,"perf_q"),"0.0%"),"") -> 50d:10.3% 200d:-14.4% 1m:26.9% 3m:0.5% | H6: =_xldudf_optionsamurai_stock(A6,"perf_m") -> 0.2689 | I6: =_xldudf_optionsamurai_stock(A6,"perf_q") -> 0.0052 | J6: =_xldudf_optionsamurai_option(A6,"CALL",$B$3,"1.5%","strike") -> 12 | K6: =_xldudf_optionsamurai_option(A6,"CALL",$B$3,"1.5%","bid") -> 0.38 | L6: =_xldudf_optionsamurai_option(A6,"PUT",$B$3,"-1.5%","strike") -> 11.5 | M6: =_xldudf_optionsamurai_option(A6,"PUT",$B$3,"-1.5%","bid") -> 0.55 | N6: =K6+M6 -> 0.93 | O6: =IF(B6>0,N6/B6,"") -> 0.080103359 | P6: =_xldudf_optionsamurai_option(A6,"CALL",$B$3,"1.5%","strike") -> 12 | Q6: =_xldudf_optionsamurai_option(A6,"CALL",$B$3,"1.5%","bid") -> 0.38 | R6: =IF(B6>0,Q6/B6,"") -> 0.032730405 | S6: =_xldudf_optionsamurai_option(A6,"PUT",$B$3,"-1.5%","strike") -> 11.5 | T6: =_xldudf_optionsamurai_option(A6,"PUT",$B$3,"-1.5%","bid") -> 0.55 | U6: =IF(B6>0,T6/B6,"") -> 0.047372954 | V6: =_xldudf_optionsamurai_stock(A6,"earnings_date") -> 2026-05-04 | W6: =_xldudf_optionsamurai_option(A6,"CALL",$B$3,"1.5%","delta") -> 0.436025 | X6: =ABS(_xldudf_optionsamurai_option(A6,"PUT",$B$3,"-1.5%","delta")) -> 0.440604 | Y6: =IF(AND(ISNUMBER(W6),ISNUMBER(X6)),1-W6-X6,"") -> 0.123371 | Z6: =IF(ISNUMBER(Y6),1-Y6,"") -> 0.876629 | AA6: =IF(AND(ISNUMBER(J6),ISNUMBER(B6),B6>0),(J6-B6)/B6,"") -> 0.033591731 | AB6: =IF(AND(ISNUMBER(L6),ISNUMBER(B6),B6>0),(B6-L6)/B6,"") -> 0.0094745909 | AC6: =IF(AND(ISNUMBER(J6),ISNUMBER(L6)),J6-L6,"") -> 0.5 | AD6: =IF(AND(ISNUMBER(Y6),Y6>0.05,ISNUMBER(AA6),AA6>0.015,ISNUMBER(AB6),AB6>0.015,ISNUMBER(W6),W6<0.5,ISNUMBER(X6),X6<0.5,ISNUMBER(AC6),AC6>0,ISNUMBER(F6),F6>=2),"✅ YES","🚫 NO") -> 🚫 NO | AE6: =_xldudf_optionsamurai_option(A6,"CALL",$B$3,"25d","strike") -> 13 | AF6: =_xldudf_optionsamurai_option(A6,"CALL",$B$3,"25d","bid") -> 0.21 | AG6: =_xldudf_optionsamurai_option(A6,"PUT",$B$3,"25d","strike") -> 10.5 | AH6: =_xldudf_optionsamurai_option(A6,"PUT",$B$3,"25d","bid") -> 0.22 | AI6: =_xldudf_optionsamurai_option(A6,"CALL",$B$3,TEXT(J6,"0"),"prob_otm") -> 0.61669 | AJ6: =_xldudf_optionsamurai_option(A6,"PUT",$B$3,TEXT(L6,"0"),"prob_otm") -> 0.38331 | AK6: =IF(AND(ISNUMBER(AI6),ISNUMBER(AJ6)),AI6*AJ6,"") -> 0.23638344 | AL6: =_xldudf_optionsamurai_stock(A6,"stock_iv_rv_pr") -> N/A | AM6: =_xldudf_optionsamurai_stock(A6,"atr_percent") -> 0.042205 | AN6: =_xldudf_optionsamurai_stock(A6,"short_ratio") -> 6.02 | AO6: =IF(ISNUMBER(AL6),IF(AL6>=0.6,"🟢 IV>RV",IF(AL6>=0.3,"🟡 Moderate","🔴 IV<RV")),"") | AP6: =IF(ISNUMBER(AM6),IF(AM6<=0.02,"🟢 Smooth",IF(AM6<=0.04,"🟡 Moderate","🔴 Choppy")),"") -> 🔴 Choppy | AS6: =IF(ISNUMBER(AQ6),MAX(0,B6-J6),"") | AT6: =IF(ISNUMBER(AR6),MAX(0,L6-B6),"") | AU6: =IF(AND(ISNUMBER(AQ6),ISNUMBER(AR6)),(AQ6+AR6-IF(ISNUMBER(AS6),AS6,0)-IF(ISNUMBER(AT6),AT6,0))*100,"")
A7: DECK | B7: =_xldudf_optionsamurai_stock(A7,"stock_last") -> 110.17 | C7: =_xldudf_optionsamurai_stock(A7,"stock_iv") -> 0.4083 | D7: =_xldudf_optionsamurai_stock(A7,"sector") -> Consumer Cyclical | E7: =_xldudf_optionsamurai_stock(A7,"industry") -> Footwear & Accessories | F7: =IF(AND(ISNUMBER(_xldudf_optionsamurai_stock(A7,"sma_50d")),ISNUMBER(_xldudf_optionsamurai_stock(A7,"sma_200d")),ISNUMBER(_xldudf_optionsamurai_stock(A7,"perf_m")),ISNUMBER(_xldudf_optionsamurai_stock(A7,"perf_q"))),(_xldudf_optionsamurai_stock(A7,"sma_50d")>0)*1+(_xldudf_optionsamurai_stock(A7,"sma_200d")>0)*1+(_xldudf_optionsamurai_stock(A7,"perf_m")>0)*1+(_xldudf_optionsamurai_stock(A7,"perf_q")>0)*1,"") -> 4 | G7: =IF(ISNUMBER(_xldudf_optionsamurai_stock(A7,"sma_50d")),"50d:"&TEXT(_xldudf_optionsamurai_stock(A7,"sma_50d"),"0.0%")&" 200d:"&TEXT(_xldudf_optionsamurai_stock(A7,"sma_200d"),"0.0%")&" 1m:"&TEXT(_xldudf_optionsamurai_stock(A7,"perf_m"),"0.0%")&" 3m:"&TEXT(_xldudf_optionsamurai_stock(A7,"perf_q"),"0.0%"),"") -> 50d:2.0% 200d:6.5% 1m:9.7% 3m:12.4% | H7: =_xldudf_optionsamurai_stock(A7,"perf_m") -> 0.097 | I7: =_xldudf_optionsamurai_stock(A7,"perf_q") -> 0.1244 | J7: =_xldudf_optionsamurai_option(A7,"CALL",$B$3,"1.5%","strike") -> 112 | K7: =_xldudf_optionsamurai_option(A7,"CALL",$B$3,"1.5%","bid") -> 2.7 | L7: =_xldudf_optionsamurai_option(A7,"PUT",$B$3,"-1.5%","strike") -> 109 | M7: =_xldudf_optionsamurai_option(A7,"PUT",$B$3,"-1.5%","bid") -> 2.85 | N7: =K7+M7 -> 5.55 | O7: =IF(B7>0,N7/B7,"") -> 0.050376691 | P7: =_xldudf_optionsamurai_option(A7,"CALL",$B$3,"1.5%","strike") -> 112 | Q7: =_xldudf_optionsamurai_option(A7,"CALL",$B$3,"1.5%","bid") -> 2.7 | R7: =IF(B7>0,Q7/B7,"") -> 0.024507579 | S7: =_xldudf_optionsamurai_option(A7,"PUT",$B$3,"-1.5%","strike") -> 109 | T7: =_xldudf_optionsamurai_option(A7,"PUT",$B$3,"-1.5%","bid") -> 2.85 | U7: =IF(B7>0,T7/B7,"") -> 0.025869111 | V7: =_xldudf_optionsamurai_stock(A7,"earnings_date") -> 2026-05-21 | W7: =_xldudf_optionsamurai_option(A7,"CALL",$B$3,"1.5%","delta") -> 0.445216 | X7: =ABS(_xldudf_optionsamurai_option(A7,"PUT",$B$3,"-1.5%","delta")) -> 0.425637 | Y7: =IF(AND(ISNUMBER(W7),ISNUMBER(X7)),1-W7-X7,"") -> 0.129147 | Z7: =IF(ISNUMBER(Y7),1-Y7,"") -> 0.870853 | AA7: =IF(AND(ISNUMBER(J7),ISNUMBER(B7),B7>0),(J7-B7)/B7,"") -> 0.016610693 | AB7: =IF(AND(ISNUMBER(L7),ISNUMBER(B7),B7>0),(B7-L7)/B7,"") -> 0.010619951 | AC7: =IF(AND(ISNUMBER(J7),ISNUMBER(L7)),J7-L7,"") -> 3 | AD7: =IF(AND(ISNUMBER(Y7),Y7>0.05,ISNUMBER(AA7),AA7>0.015,ISNUMBER(AB7),AB7>0.015,ISNUMBER(W7),W7<0.5,ISNUMBER(X7),X7<0.5,ISNUMBER(AC7),AC7>0,ISNUMBER(F7),F7>=2),"✅ YES","🚫 NO") -> 🚫 NO | AE7: =_xldudf_optionsamurai_option(A7,"CALL",$B$3,"25d","strike") -> 125 | AF7: =_xldudf_optionsamurai_option(A7,"CALL",$B$3,"25d","bid") -> N/A | AG7: =_xldudf_optionsamurai_option(A7,"PUT",$B$3,"25d","strike") -> 104 | AH7: =_xldudf_optionsamurai_option(A7,"PUT",$B$3,"25d","bid") -> 1.25 | AI7: =_xldudf_optionsamurai_option(A7,"CALL",$B$3,TEXT(J7,"0"),"prob_otm") -> 0.58454 | AJ7: =_xldudf_optionsamurai_option(A7,"PUT",$B$3,TEXT(L7,"0"),"prob_otm") -> 0.538834 | AK7: =IF(AND(ISNUMBER(AI7),ISNUMBER(AJ7)),AI7*AJ7,"") -> 0.31497003 | AL7: =_xldudf_optionsamurai_stock(A7,"stock_iv_rv_pr") -> 0.603175 | AM7: =_xldudf_optionsamurai_stock(A7,"atr_percent") -> 0.035218 | AN7: =_xldudf_optionsamurai_stock(A7,"short_ratio") -> 1.57 | AO7: =IF(ISNUMBER(AL7),IF(AL7>=0.6,"🟢 IV>RV",IF(AL7>=0.3,"🟡 Moderate","🔴 IV<RV")),"") -> 🟢 IV>RV | AP7: =IF(ISNUMBER(AM7),IF(AM7<=0.02,"🟢 Smooth",IF(AM7<=0.04,"🟡 Moderate","🔴 Choppy")),"") -> 🟡 Moderate | AS7: =IF(ISNUMBER(AQ7),MAX(0,B7-J7),"") | AT7: =IF(ISNUMBER(AR7),MAX(0,L7-B7),"") | AU7: =IF(AND(ISNUMBER(AQ7),ISNUMBER(AR7)),(AQ7+AR7-IF(ISNUMBER(AS7),AS7,0)-IF(ISNUMBER(AT7),AT7,0))*100,"")
A8: GME | B8: =_xldudf_optionsamurai_stock(A8,"stock_last") -> 24.46 | C8: =_xldudf_optionsamurai_stock(A8,"stock_iv") -> 0.448 | D8: =_xldudf_optionsamurai_stock(A8,"sector") -> Consumer Cyclical | E8: =_xldudf_optionsamurai_stock(A8,"industry") -> Specialty Retail | F8: =IF(AND(ISNUMBER(_xldudf_optionsamurai_stock(A8,"sma_50d")),ISNUMBER(_xldudf_optionsamurai_stock(A8,"sma_200d")),ISNUMBER(_xldudf_optionsamurai_stock(A8,"perf_m")),ISNUMBER(_xldudf_optionsamurai_stock(A8,"perf_q"))),(_xldudf_optionsamurai_stock(A8,"sma_50d")>0)*1+(_xldudf_optionsamurai_stock(A8,"sma_200d")>0)*1+(_xldudf_optionsamurai_stock(A8,"perf_m")>0)*1+(_xldudf_optionsamurai_stock(A8,"perf_q")>0)*1,"") -> 4 | G8: =IF(ISNUMBER(_xldudf_optionsamurai_stock(A8,"sma_50d")),"50d:"&TEXT(_xldudf_optionsamurai_stock(A8,"sma_50d"),"0.0%")&" 200d:"&TEXT(_xldudf_optionsamurai_stock(A8,"sma_200d"),"0.0%")&" 1m:"&TEXT(_xldudf_optionsamurai_stock(A8,"perf_m"),"0.0%")&" 3m:"&TEXT(_xldudf_optionsamurai_stock(A8,"perf_q"),"0.0%"),"") -> 50d:3.2% 200d:5.6% 1m:8.4% 3m:15.9% | H8: =_xldudf_optionsamurai_stock(A8,"perf_m") -> 0.0837 | I8: =_xldudf_optionsamurai_stock(A8,"perf_q") -> 0.1592 | J8: =_xldudf_optionsamurai_option(A8,"CALL",$B$3,"1.5%","strike") -> 25 | K8: =_xldudf_optionsamurai_option(A8,"CALL",$B$3,"1.5%","bid") -> 0.64 | L8: =_xldudf_optionsamurai_option(A8,"PUT",$B$3,"-1.5%","strike") -> 24 | M8: =_xldudf_optionsamurai_option(A8,"PUT",$B$3,"-1.5%","bid") -> 0.37 | N8: =K8+M8 -> 1.01 | O8: =IF(B8>0,N8/B8,"") -> 0.041291905 | P8: =_xldudf_optionsamurai_option(A8,"CALL",$B$3,"1.5%","strike") -> 25 | Q8: =_xldudf_optionsamurai_option(A8,"CALL",$B$3,"1.5%","bid") -> 0.64 | R8: =IF(B8>0,Q8/B8,"") -> 0.026165168 | S8: =_xldudf_optionsamurai_option(A8,"PUT",$B$3,"-1.5%","strike") -> 24 | T8: =_xldudf_optionsamurai_option(A8,"PUT",$B$3,"-1.5%","bid") -> 0.37 | U8: =IF(B8>0,T8/B8,"") -> 0.015126738 | V8: =_xldudf_optionsamurai_stock(A8,"earnings_date") -> 2026-06-09 | W8: =_xldudf_optionsamurai_option(A8,"CALL",$B$3,"1.5%","delta") -> 0.430086 | X8: =ABS(_xldudf_optionsamurai_option(A8,"PUT",$B$3,"-1.5%","delta")) -> 0.371501 | Y8: =IF(AND(ISNUMBER(W8),ISNUMBER(X8)),1-W8-X8,"") -> 0.198413 | Z8: =IF(ISNUMBER(Y8),1-Y8,"") -> 0.801587 | AA8: =IF(AND(ISNUMBER(J8),ISNUMBER(B8),B8>0),(J8-B8)/B8,"") -> 0.02207686 | AB8: =IF(AND(ISNUMBER(L8),ISNUMBER(B8),B8>0),(B8-L8)/B8,"") -> 0.018806214 | AC8: =IF(AND(ISNUMBER(J8),ISNUMBER(L8)),J8-L8,"") -> 1 | AD8: =IF(AND(ISNUMBER(Y8),Y8>0.05,ISNUMBER(AA8),AA8>0.015,ISNUMBER(AB8),AB8>0.015,ISNUMBER(W8),W8<0.5,ISNUMBER(X8),X8<0.5,ISNUMBER(AC8),AC8>0,ISNUMBER(F8),F8>=2),"✅ YES","🚫 NO") -> ✅ YES | AE8: =_xldudf_optionsamurai_option(A8,"CALL",$B$3,"25d","strike") -> 26.5 | AF8: =_xldudf_optionsamurai_option(A8,"CALL",$B$3,"25d","bid") -> 0.19 | AG8: =_xldudf_optionsamurai_option(A8,"PUT",$B$3,"25d","strike") -> 23.5 | AH8: =_xldudf_optionsamurai_option(A8,"PUT",$B$3,"25d","bid") -> 0.22 | AI8: =_xldudf_optionsamurai_option(A8,"CALL",$B$3,TEXT(J8,"0"),"prob_otm") -> 0.602048 | AJ8: =_xldudf_optionsamurai_option(A8,"PUT",$B$3,TEXT(L8,"0"),"prob_otm") -> 0.566485 | AK8: =IF(AND(ISNUMBER(AI8),ISNUMBER(AJ8)),AI8*AJ8,"") -> 0.34105116 | AL8: =_xldudf_optionsamurai_stock(A8,"stock_iv_rv_pr") -> 0.488095 | AM8: =_xldudf_optionsamurai_stock(A8,"atr_percent") -> 0.032706 | AN8: =_xldudf_optionsamurai_stock(A8,"short_ratio") -> 8.13 | AO8: =IF(ISNUMBER(AL8),IF(AL8>=0.6,"🟢 IV>RV",IF(AL8>=0.3,"🟡 Moderate","🔴 IV<RV")),"") -> 🟡 Moderate | AP8: =IF(ISNUMBER(AM8),IF(AM8<=0.02,"🟢 Smooth",IF(AM8<=0.04,"🟡 Moderate","🔴 Choppy")),"") -> 🟡 Moderate | AS8: =IF(ISNUMBER(AQ8),MAX(0,B8-J8),"") | AT8: =IF(ISNUMBER(AR8),MAX(0,L8-B8),"") | AU8: =IF(AND(ISNUMBER(AQ8),ISNUMBER(AR8)),(AQ8+AR8-IF(ISNUMBER(AS8),AS8,0)-IF(ISNUMBER(AT8),AT8,0))*100,"")
A9: JD | B9: =_xldudf_optionsamurai_stock(A9,"stock_last") -> 30.52 | C9: =_xldudf_optionsamurai_stock(A9,"stock_iv") -> 0.4463 | D9: =_xldudf_optionsamurai_stock(A9,"sector") -> Consumer Cyclical | E9: =_xldudf_optionsamurai_stock(A9,"industry") -> Internet Retail | F9: =IF(AND(ISNUMBER(_xldudf_optionsamurai_stock(A9,"sma_50d")),ISNUMBER(_xldudf_optionsamurai_stock(A9,"sma_200d")),ISNUMBER(_xldudf_optionsamurai_stock(A9,"perf_m")),ISNUMBER(_xldudf_optionsamurai_stock(A9,"perf_q"))),(_xldudf_optionsamurai_stock(A9,"sma_50d")>0)*1+(_xldudf_optionsamurai_stock(A9,"sma_200d")>0)*1+(_xldudf_optionsamurai_stock(A9,"perf_m")>0)*1+(_xldudf_optionsamurai_stock(A9,"perf_q")>0)*1,"") -> 3 | G9: =IF(ISNUMBER(_xldudf_optionsamurai_stock(A9,"sma_50d")),"50d:"&TEXT(_xldudf_optionsamurai_stock(A9,"sma_50d"),"0.0%")&" 200d:"&TEXT(_xldudf_optionsamurai_stock(A9,"sma_200d"),"0.0%")&" 1m:"&TEXT(_xldudf_optionsamurai_stock(A9,"perf_m"),"0.0%")&" 3m:"&TEXT(_xldudf_optionsamurai_stock(A9,"perf_q"),"0.0%"),"") -> 50d:8.0% 200d:-0.4% 1m:11.9% 3m:7.5% | H9: =_xldudf_optionsamurai_stock(A9,"perf_m") -> 0.1192 | I9: =_xldudf_optionsamurai_stock(A9,"perf_q") -> 0.0754 | J9: =_xldudf_optionsamurai_option(A9,"CALL",$B$3,"1.5%","strike") -> 31 | K9: =_xldudf_optionsamurai_option(A9,"CALL",$B$3,"1.5%","bid") -> 0.65 | L9: =_xldudf_optionsamurai_option(A9,"PUT",$B$3,"-1.5%","strike") -> 30 | M9: =_xldudf_optionsamurai_option(A9,"PUT",$B$3,"-1.5%","bid") -> 0.66 | N9: =K9+M9 -> 1.31 | O9: =IF(B9>0,N9/B9,"") -> 0.042922674 | P9: =_xldudf_optionsamurai_option(A9,"CALL",$B$3,"1.5%","strike") -> 31 | Q9: =_xldudf_optionsamurai_option(A9,"CALL",$B$3,"1.5%","bid") -> 0.65 | R9: =IF(B9>0,Q9/B9,"") -> 0.02129751 | S9: =_xldudf_optionsamurai_option(A9,"PUT",$B$3,"-1.5%","strike") -> 30 | T9: =_xldudf_optionsamurai_option(A9,"PUT",$B$3,"-1.5%","bid") -> 0.66 | U9: =IF(B9>0,T9/B9,"") -> 0.021625164 | V9: =_xldudf_optionsamurai_stock(A9,"earnings_date") -> 2026-05-12 | W9: =_xldudf_optionsamurai_option(A9,"CALL",$B$3,"1.5%","delta") -> 0.457467 | X9: =ABS(_xldudf_optionsamurai_option(A9,"PUT",$B$3,"-1.5%","delta")) -> 0.391781 | Y9: =IF(AND(ISNUMBER(W9),ISNUMBER(X9)),1-W9-X9,"") -> 0.150752 | Z9: =IF(ISNUMBER(Y9),1-Y9,"") -> 0.849248 | AA9: =IF(AND(ISNUMBER(J9),ISNUMBER(B9),B9>0),(J9-B9)/B9,"") -> 0.015727392 | AB9: =IF(AND(ISNUMBER(L9),ISNUMBER(B9),B9>0),(B9-L9)/B9,"") -> 0.017038008 | AC9: =IF(AND(ISNUMBER(J9),ISNUMBER(L9)),J9-L9,"") -> 1 | AD9: =IF(AND(ISNUMBER(Y9),Y9>0.05,ISNUMBER(AA9),AA9>0.015,ISNUMBER(AB9),AB9>0.015,ISNUMBER(W9),W9<0.5,ISNUMBER(X9),X9<0.5,ISNUMBER(AC9),AC9>0,ISNUMBER(F9),F9>=2),"✅ YES","🚫 NO") -> ✅ YES | AE9: =_xldudf_optionsamurai_option(A9,"CALL",$B$3,"25d","strike") -> 37 | AF9: =_xldudf_optionsamurai_option(A9,"CALL",$B$3,"25d","bid") -> N/A | AG9: =_xldudf_optionsamurai_option(A9,"PUT",$B$3,"25d","strike") -> 29 | AH9: =_xldudf_optionsamurai_option(A9,"PUT",$B$3,"25d","bid") -> 0.33 | AI9: =_xldudf_optionsamurai_option(A9,"CALL",$B$3,TEXT(J9,"0"),"prob_otm") -> 0.576908 | AJ9: =_xldudf_optionsamurai_option(A9,"PUT",$B$3,TEXT(L9,"0"),"prob_otm") -> 0.559454 | AK9: =IF(AND(ISNUMBER(AI9),ISNUMBER(AJ9)),AI9*AJ9,"") -> 0.32275349 | AL9: =_xldudf_optionsamurai_stock(A9,"stock_iv_rv_pr") -> 0.27381 | AM9: =_xldudf_optionsamurai_stock(A9,"atr_percent") -> 0.027195 | AN9: =_xldudf_optionsamurai_stock(A9,"short_ratio") -> 2.42 | AO9: =IF(ISNUMBER(AL9),IF(AL9>=0.6,"🟢 IV>RV",IF(AL9>=0.3,"🟡 Moderate","🔴 IV<RV")),"") -> 🔴 IV<RV | AP9: =IF(ISNUMBER(AM9),IF(AM9<=0.02,"🟢 Smooth",IF(AM9<=0.04,"🟡 Moderate","🔴 Choppy")),"") -> 🟡 Moderate | AS9: =IF(ISNUMBER(AQ9),MAX(0,B9-J9),"") | AT9: =IF(ISNUMBER(AR9),MAX(0,L9-B9),"") | AU9: =IF(AND(ISNUMBER(AQ9),ISNUMBER(AR9)),(AQ9+AR9-IF(ISNUMBER(AS9),AS9,0)-IF(ISNUMBER(AT9),AT9,0))*100,"")
A10: URBN | B10: =_xldudf_optionsamurai_stock(A10,"stock_last") -> 74.71 | C10: =_xldudf_optionsamurai_stock(A10,"stock_iv") -> 0.4476 | D10: =_xldudf_optionsamurai_stock(A10,"sector") -> Consumer Cyclical | E10: =_xldudf_optionsamurai_stock(A10,"industry") -> Apparel Retail | F10: =IF(AND(ISNUMBER(_xldudf_optionsamurai_stock(A10,"sma_50d")),ISNUMBER(_xldudf_optionsamurai_stock(A10,"sma_200d")),ISNUMBER(_xldudf_optionsamurai_stock(A10,"perf_m")),ISNUMBER(_xldudf_optionsamurai_stock(A10,"perf_q"))),(_xldudf_optionsamurai_stock(A10,"sma_50d")>0)*1+(_xldudf_optionsamurai_stock(A10,"sma_200d")>0)*1+(_xldudf_optionsamurai_stock(A10,"perf_m")>0)*1+(_xldudf_optionsamurai_stock(A10,"perf_q")>0)*1,"") -> 4 | G10: =IF(ISNUMBER(_xldudf_optionsamurai_stock(A10,"sma_50d")),"50d:"&TEXT(_xldudf_optionsamurai_stock(A10,"sma_50d"),"0.0%")&" 200d:"&TEXT(_xldudf_optionsamurai_stock(A10,"sma_200d"),"0.0%")&" 1m:"&TEXT(_xldudf_optionsamurai_stock(A10,"perf_m"),"0.0%")&" 3m:"&TEXT(_xldudf_optionsamurai_stock(A10,"perf_q"),"0.0%"),"") -> 50d:12.3% 200d:5.5% 1m:17.9% 3m:6.3% | H10: =_xldudf_optionsamurai_stock(A10,"perf_m") -> 0.1786 | I10: =_xldudf_optionsamurai_stock(A10,"perf_q") -> 0.0629 | J10: =_xldudf_optionsamurai_option(A10,"CALL",$B$3,"1.5%","strike") -> 76 | K10: =_xldudf_optionsamurai_option(A10,"CALL",$B$3,"1.5%","bid") -> 2.1 | L10: =_xldudf_optionsamurai_option(A10,"PUT",$B$3,"-1.5%","strike") -> 74 | M10: =_xldudf_optionsamurai_option(A10,"PUT",$B$3,"-1.5%","bid") -> 2.15 | N10: =K10+M10 -> 4.25 | O10: =IF(B10>0,N10/B10,"") -> 0.056886628 | P10: =_xldudf_optionsamurai_option(A10,"CALL",$B$3,"1.5%","strike") -> 76 | Q10: =_xldudf_optionsamurai_option(A10,"CALL",$B$3,"1.5%","bid") -> 2.1 | R10: =IF(B10>0,Q10/B10,"") -> 0.028108687 | S10: =_xldudf_optionsamurai_option(A10,"PUT",$B$3,"-1.5%","strike") -> 74 | T10: =_xldudf_optionsamurai_option(A10,"PUT",$B$3,"-1.5%","bid") -> 2.15 | U10: =IF(B10>0,T10/B10,"") -> 0.028777941 | V10: =_xldudf_optionsamurai_stock(A10,"earnings_date") -> 2026-05-20 | W10: =_xldudf_optionsamurai_option(A10,"CALL",$B$3,"1.5%","delta") -> 0.455309 | X10: =ABS(_xldudf_optionsamurai_option(A10,"PUT",$B$3,"-1.5%","delta")) -> 0.43465 | Y10: =IF(AND(ISNUMBER(W10),ISNUMBER(X10)),1-W10-X10,"") -> 0.110041 | Z10: =IF(ISNUMBER(Y10),1-Y10,"") -> 0.889959 | AA10: =IF(AND(ISNUMBER(J10),ISNUMBER(B10),B10>0),(J10-B10)/B10,"") -> 0.017266765 | AB10: =IF(AND(ISNUMBER(L10),ISNUMBER(B10),B10>0),(B10-L10)/B10,"") -> 0.0095034132 | AC10: =IF(AND(ISNUMBER(J10),ISNUMBER(L10)),J10-L10,"") -> 2 | AD10: =IF(AND(ISNUMBER(Y10),Y10>0.05,ISNUMBER(AA10),AA10>0.015,ISNUMBER(AB10),AB10>0.015,ISNUMBER(W10),W10<0.5,ISNUMBER(X10),X10<0.5,ISNUMBER(AC10),AC10>0,ISNUMBER(F10),F10>=2),"✅ YES","🚫 NO") -> 🚫 NO | AE10: =_xldudf_optionsamurai_option(A10,"CALL",$B$3,"25d","strike") -> 80 | AF10: =_xldudf_optionsamurai_option(A10,"CALL",$B$3,"25d","bid") -> 0.7 | AG10: =_xldudf_optionsamurai_option(A10,"PUT",$B$3,"25d","strike") -> 70 | AH10: =_xldudf_optionsamurai_option(A10,"PUT",$B$3,"25d","bid") -> 0.75 | AI10: =_xldudf_optionsamurai_option(A10,"CALL",$B$3,TEXT(J10,"0"),"prob_otm") -> 0.582989 | AJ10: =_xldudf_optionsamurai_option(A10,"PUT",$B$3,TEXT(L10,"0"),"prob_otm") -> 0.52755 | AK10: =IF(AND(ISNUMBER(AI10),ISNUMBER(AJ10)),AI10*AJ10,"") -> 0.30755585 | AL10: =_xldudf_optionsamurai_stock(A10,"stock_iv_rv_pr") -> 0.535714 | AM10: =_xldudf_optionsamurai_stock(A10,"atr_percent") -> 0.038951 | AN10: =_xldudf_optionsamurai_stock(A10,"short_ratio") -> 4.92 | AO10: =IF(ISNUMBER(AL10),IF(AL10>=0.6,"🟢 IV>RV",IF(AL10>=0.3,"🟡 Moderate","🔴 IV<RV")),"") -> 🟡 Moderate | AP10: =IF(ISNUMBER(AM10),IF(AM10<=0.02,"🟢 Smooth",IF(AM10<=0.04,"🟡 Moderate","🔴 Choppy")),"") -> 🟡 Moderate | AS10: =IF(ISNUMBER(AQ10),MAX(0,B10-J10),"") | AT10: =IF(ISNUMBER(AR10),MAX(0,L10-B10),"") | AU10: =IF(AND(ISNUMBER(AQ10),ISNUMBER(AR10)),(AQ10+AR10-IF(ISNUMBER(AS10),AS10,0)-IF(ISNUMBER(AT10),AT10,0))*100,"")
A11: BUD | B11: =_xldudf_optionsamurai_stock(A11,"stock_last") -> 72.78 | C11: =_xldudf_optionsamurai_stock(A11,"stock_iv") -> 0.3157 | D11: =_xldudf_optionsamurai_stock(A11,"sector") -> Consumer Defensive | E11: =_xldudf_optionsamurai_stock(A11,"industry") -> Beverages - Brewers | F11: =IF(AND(ISNUMBER(_xldudf_optionsamurai_stock(A11,"sma_50d")),ISNUMBER(_xldudf_optionsamurai_stock(A11,"sma_200d")),ISNUMBER(_xldudf_optionsamurai_stock(A11,"perf_m")),ISNUMBER(_xldudf_optionsamurai_stock(A11,"perf_q"))),(_xldudf_optionsamurai_stock(A11,"sma_50d")>0)*1+(_xldudf_optionsamurai_stock(A11,"sma_200d")>0)*1+(_xldudf_optionsamurai_stock(A11,"perf_m")>0)*1+(_xldudf_optionsamurai_stock(A11,"perf_q")>0)*1,"") -> 3 | G11: =IF(ISNUMBER(_xldudf_optionsamurai_stock(A11,"sma_50d")),"50d:"&TEXT(_xldudf_optionsamurai_stock(A11,"sma_50d"),"0.0%")&" 200d:"&TEXT(_xldudf_optionsamurai_stock(A11,"sma_200d"),"0.0%")&" 1m:"&TEXT(_xldudf_optionsamurai_stock(A11,"perf_m"),"0.0%")&" 3m:"&TEXT(_xldudf_optionsamurai_stock(A11,"perf_q"),"0.0%"),"") -> 50d:-2.0% 200d:10.0% 1m:7.9% 3m:5.7% | H11: =_xldudf_optionsamurai_stock(A11,"perf_m") -> 0.0785 | I11: =_xldudf_optionsamurai_stock(A11,"perf_q") -> 0.0565 | J11: =_xldudf_optionsamurai_option(A11,"CALL",$B$3,"1.5%","strike") -> 74 | K11: =_xldudf_optionsamurai_option(A11,"CALL",$B$3,"1.5%","bid") -> 1.45 | L11: =_xldudf_optionsamurai_option(A11,"PUT",$B$3,"-1.5%","strike") -> 72 | M11: =_xldudf_optionsamurai_option(A11,"PUT",$B$3,"-1.5%","bid") -> 2 | N11: =K11+M11 -> 3.45 | O11: =IF(B11>0,N11/B11,"") -> 0.047403133 | P11: =_xldudf_optionsamurai_option(A11,"CALL",$B$3,"1.5%","strike") -> 74 | Q11: =_xldudf_optionsamurai_option(A11,"CALL",$B$3,"1.5%","bid") -> 1.45 | R11: =IF(B11>0,Q11/B11,"") -> 0.019923056 | S11: =_xldudf_optionsamurai_option(A11,"PUT",$B$3,"-1.5%","strike") -> 72 | T11: =_xldudf_optionsamurai_option(A11,"PUT",$B$3,"-1.5%","bid") -> 2 | U11: =IF(B11>0,T11/B11,"") -> 0.027480077 | V11: =_xldudf_optionsamurai_stock(A11,"earnings_date") -> 2026-05-05 | W11: =_xldudf_optionsamurai_option(A11,"CALL",$B$3,"1.5%","delta") -> 0.434999 | X11: =ABS(_xldudf_optionsamurai_option(A11,"PUT",$B$3,"-1.5%","delta")) -> 0.428136 | Y11: =IF(AND(ISNUMBER(W11),ISNUMBER(X11)),1-W11-X11,"") -> 0.136865 | Z11: =IF(ISNUMBER(Y11),1-Y11,"") -> 0.863135 | AA11: =IF(AND(ISNUMBER(J11),ISNUMBER(B11),B11>0),(J11-B11)/B11,"") -> 0.016762847 | AB11: =IF(AND(ISNUMBER(L11),ISNUMBER(B11),B11>0),(B11-L11)/B11,"") -> 0.01071723 | AC11: =IF(AND(ISNUMBER(J11),ISNUMBER(L11)),J11-L11,"") -> 2 | AD11: =IF(AND(ISNUMBER(Y11),Y11>0.05,ISNUMBER(AA11),AA11>0.015,ISNUMBER(AB11),AB11>0.015,ISNUMBER(W11),W11<0.5,ISNUMBER(X11),X11<0.5,ISNUMBER(AC11),AC11>0,ISNUMBER(F11),F11>=2),"✅ YES","🚫 NO") -> 🚫 NO | AE11: =_xldudf_optionsamurai_option(A11,"CALL",$B$3,"25d","strike") -> 87 | AF11: =_xldudf_optionsamurai_option(A11,"CALL",$B$3,"25d","bid") -> N/A | AG11: =_xldudf_optionsamurai_option(A11,"PUT",$B$3,"25d","strike") -> 69 | AH11: =_xldudf_optionsamurai_option(A11,"PUT",$B$3,"25d","bid") -> 0.9 | AI11: =_xldudf_optionsamurai_option(A11,"CALL",$B$3,TEXT(J11,"0"),"prob_otm") -> 0.600909 | AJ11: =_xldudf_optionsamurai_option(A11,"PUT",$B$3,TEXT(L11,"0"),"prob_otm") -> 0.559727 | AK11: =IF(AND(ISNUMBER(AI11),ISNUMBER(AJ11)),AI11*AJ11,"") -> 0.33634499 | AL11: =_xldudf_optionsamurai_stock(A11,"stock_iv_rv_pr") -> 0.65873 | AM11: =_xldudf_optionsamurai_stock(A11,"atr_percent") -> 0.019923 | AN11: =_xldudf_optionsamurai_stock(A11,"short_ratio") -> 2.33 | AO11: =IF(ISNUMBER(AL11),IF(AL11>=0.6,"🟢 IV>RV",IF(AL11>=0.3,"🟡 Moderate","🔴 IV<RV")),"") -> 🟢 IV>RV | AP11: =IF(ISNUMBER(AM11),IF(AM11<=0.02,"🟢 Smooth",IF(AM11<=0.04,"🟡 Moderate","🔴 Choppy")),"") -> 🟢 Smooth | AS11: =IF(ISNUMBER(AQ11),MAX(0,B11-J11),"") | AT11: =IF(ISNUMBER(AR11),MAX(0,L11-B11),"") | AU11: =IF(AND(ISNUMBER(AQ11),ISNUMBER(AR11)),(AQ11+AR11-IF(ISNUMBER(AS11),AS11,0)-IF(ISNUMBER(AT11),AT11,0))*100,"")
A12: UEC | B12: =_xldudf_optionsamurai_stock(A12,"stock_last") -> 14.45 | C12: =_xldudf_optionsamurai_stock(A12,"stock_iv") -> 0.7824 | D12: =_xldudf_optionsamurai_stock(A12,"sector") -> Energy | E12: =_xldudf_optionsamurai_stock(A12,"industry") -> Uranium | F12: =IF(AND(ISNUMBER(_xldudf_optionsamurai_stock(A12,"sma_50d")),ISNUMBER(_xldudf_optionsamurai_stock(A12,"sma_200d")),ISNUMBER(_xldudf_optionsamurai_stock(A12,"perf_m")),ISNUMBER(_xldudf_optionsamurai_stock(A12,"perf_q"))),(_xldudf_optionsamurai_stock(A12,"sma_50d")>0)*1+(_xldudf_optionsamurai_stock(A12,"sma_200d")>0)*1+(_xldudf_optionsamurai_stock(A12,"perf_m")>0)*1+(_xldudf_optionsamurai_stock(A12,"perf_q")>0)*1,"") -> 3 | G12: =IF(ISNUMBER(_xldudf_optionsamurai_stock(A12,"sma_50d")),"50d:"&TEXT(_xldudf_optionsamurai_stock(A12,"sma_50d"),"0.0%")&" 200d:"&TEXT(_xldudf_optionsamurai_stock(A12,"sma_200d"),"0.0%")&" 1m:"&TEXT(_xldudf_optionsamurai_stock(A12,"perf_m"),"0.0%")&" 3m:"&TEXT(_xldudf_optionsamurai_stock(A12,"perf_q"),"0.0%"),"") -> 50d:0.6% 200d:11.2% 1m:19.5% 3m:-20.0% | H12: =_xldudf_optionsamurai_stock(A12,"perf_m") -> 0.1952 | I12: =_xldudf_optionsamurai_stock(A12,"perf_q") -> -0.2003 | J12: =_xldudf_optionsamurai_option(A12,"CALL",$B$3,"1.5%","strike") -> 14.5 | K12: =_xldudf_optionsamurai_option(A12,"CALL",$B$3,"1.5%","bid") -> 0.93 | L12: =_xldudf_optionsamurai_option(A12,"PUT",$B$3,"-1.5%","strike") -> 14 | M12: =_xldudf_optionsamurai_option(A12,"PUT",$B$3,"-1.5%","bid") -> 0.73 | N12: =K12+M12 -> 1.66 | O12: =IF(B12>0,N12/B12,"") -> 0.11487889 | P12: =_xldudf_optionsamurai_option(A12,"CALL",$B$3,"1.5%","strike") -> 14.5 | Q12: =_xldudf_optionsamurai_option(A12,"CALL",$B$3,"1.5%","bid") -> 0.93 | R12: =IF(B12>0,Q12/B12,"") -> 0.064359862 | S12: =_xldudf_optionsamurai_option(A12,"PUT",$B$3,"-1.5%","strike") -> 14 | T12: =_xldudf_optionsamurai_option(A12,"PUT",$B$3,"-1.5%","bid") -> 0.73 | U12: =IF(B12>0,T12/B12,"") -> 0.050519031 | V12: =_xldudf_optionsamurai_stock(A12,"earnings_date") -> 2026-06-01 | W12: =_xldudf_optionsamurai_option(A12,"CALL",$B$3,"1.5%","delta") -> 0.529377 | X12: =ABS(_xldudf_optionsamurai_option(A12,"PUT",$B$3,"-1.5%","delta")) -> 0.390531 | Y12: =IF(AND(ISNUMBER(W12),ISNUMBER(X12)),1-W12-X12,"") -> 0.080092 | Z12: =IF(ISNUMBER(Y12),1-Y12,"") -> 0.919908 | AA12: =IF(AND(ISNUMBER(J12),ISNUMBER(B12),B12>0),(J12-B12)/B12,"") -> 0.0034602076 | AB12: =IF(AND(ISNUMBER(L12),ISNUMBER(B12),B12>0),(B12-L12)/B12,"") -> 0.031141869 | AC12: =IF(AND(ISNUMBER(J12),ISNUMBER(L12)),J12-L12,"") -> 0.5 | AD12: =IF(AND(ISNUMBER(Y12),Y12>0.05,ISNUMBER(AA12),AA12>0.015,ISNUMBER(AB12),AB12>0.015,ISNUMBER(W12),W12<0.5,ISNUMBER(X12),X12<0.5,ISNUMBER(AC12),AC12>0,ISNUMBER(F12),F12>=2),"✅ YES","🚫 NO") -> 🚫 NO | AE12: =_xldudf_optionsamurai_option(A12,"CALL",$B$3,"25d","strike") -> 16.5 | AF12: =_xldudf_optionsamurai_option(A12,"CALL",$B$3,"25d","bid") -> 0.31 | AG12: =_xldudf_optionsamurai_option(A12,"PUT",$B$3,"25d","strike") -> 13 | AH12: =_xldudf_optionsamurai_option(A12,"PUT",$B$3,"25d","bid") -> 0.38 | AI12: =_xldudf_optionsamurai_option(A12,"CALL",$B$3,TEXT(J12,"0"),"prob_otm") -> 0.616806 | AJ12: =_xldudf_optionsamurai_option(A12,"PUT",$B$3,TEXT(L12,"0"),"prob_otm") -> 0.545891 | AK12: =IF(AND(ISNUMBER(AI12),ISNUMBER(AJ12)),AI12*AJ12,"") -> 0.33670884 | AL12: =_xldudf_optionsamurai_stock(A12,"stock_iv_rv_pr") -> 0.789683 | AM12: =_xldudf_optionsamurai_stock(A12,"atr_percent") -> 0.06436 | AN12: =_xldudf_optionsamurai_stock(A12,"short_ratio") -> 5.59 | AO12: =IF(ISNUMBER(AL12),IF(AL12>=0.6,"🟢 IV>RV",IF(AL12>=0.3,"🟡 Moderate","🔴 IV<RV")),"") -> 🟢 IV>RV | AP12: =IF(ISNUMBER(AM12),IF(AM12<=0.02,"🟢 Smooth",IF(AM12<=0.04,"🟡 Moderate","🔴 Choppy")),"") -> 🔴 Choppy | AS12: =IF(ISNUMBER(AQ12),MAX(0,B12-J12),"") | AT12: =IF(ISNUMBER(AR12),MAX(0,L12-B12),"") | AU12: =IF(AND(ISNUMBER(AQ12),ISNUMBER(AR12)),(AQ12+AR12-IF(ISNUMBER(AS12),AS12,0)-IF(ISNUMBER(AT12),AT12,0))*100,"")
A13: EEM | B13: =_xldudf_optionsamurai_stock(A13,"stock_last") -> 62.25 | C13: =_xldudf_optionsamurai_stock(A13,"stock_iv") -> 0.2446 | D13: =_xldudf_optionsamurai_stock(A13,"sector") -> Financial | E13: =_xldudf_optionsamurai_stock(A13,"industry") -> Exchange Traded Fund | F13: =IF(AND(ISNUMBER(_xldudf_optionsamurai_stock(A13,"sma_50d")),ISNUMBER(_xldudf_optionsamurai_stock(A13,"sma_200d")),ISNUMBER(_xldudf_optionsamurai_stock(A13,"perf_m")),ISNUMBER(_xldudf_optionsamurai_stock(A13,"perf_q"))),(_xldudf_optionsamurai_stock(A13,"sma_50d")>0)*1+(_xldudf_optionsamurai_stock(A13,"sma_200d")>0)*1+(_xldudf_optionsamurai_stock(A13,"perf_m")>0)*1+(_xldudf_optionsamurai_stock(A13,"perf_q")>0)*1,"") -> 4 | G13: =IF(ISNUMBER(_xldudf_optionsamurai_stock(A13,"sma_50d")),"50d:"&TEXT(_xldudf_optionsamurai_stock(A13,"sma_50d"),"0.0%")&" 200d:"&TEXT(_xldudf_optionsamurai_stock(A13,"sma_200d"),"0.0%")&" 1m:"&TEXT(_xldudf_optionsamurai_stock(A13,"perf_m"),"0.0%")&" 3m:"&TEXT(_xldudf_optionsamurai_stock(A13,"perf_q"),"0.0%"),"") -> 50d:4.6% 200d:13.4% 1m:11.9% 3m:8.6% | H13: =_xldudf_optionsamurai_stock(A13,"perf_m") -> 0.1188 | I13: =_xldudf_optionsamurai_stock(A13,"perf_q") -> 0.0862 | J13: =_xldudf_optionsamurai_option(A13,"CALL",$B$3,"1.5%","strike") -> 63 | K13: =_xldudf_optionsamurai_option(A13,"CALL",$B$3,"1.5%","bid") -> 0.73 | L13: =_xldudf_optionsamurai_option(A13,"PUT",$B$3,"-1.5%","strike") -> 61.5 | M13: =_xldudf_optionsamurai_option(A13,"PUT",$B$3,"-1.5%","bid") -> 0.4 | N13: =K13+M13 -> 1.13 | O13: =IF(B13>0,N13/B13,"") -> 0.01815261 | P13: =_xldudf_optionsamurai_option(A13,"CALL",$B$3,"1.5%","strike") -> 63 | Q13: =_xldudf_optionsamurai_option(A13,"CALL",$B$3,"1.5%","bid") -> 0.73 | R13: =IF(B13>0,Q13/B13,"") -> 0.011726908 | S13: =_xldudf_optionsamurai_option(A13,"PUT",$B$3,"-1.5%","strike") -> 61.5 | T13: =_xldudf_optionsamurai_option(A13,"PUT",$B$3,"-1.5%","bid") -> 0.4 | U13: =IF(B13>0,T13/B13,"") -> 0.0064257028 | V13: =_xldudf_optionsamurai_stock(A13,"earnings_date") -> N/A | W13: =_xldudf_optionsamurai_option(A13,"CALL",$B$3,"1.5%","delta") -> 0.458498 | X13: =ABS(_xldudf_optionsamurai_option(A13,"PUT",$B$3,"-1.5%","delta")) -> 0.397493 | Y13: =IF(AND(ISNUMBER(W13),ISNUMBER(X13)),1-W13-X13,"") -> 0.144009 | Z13: =IF(ISNUMBER(Y13),1-Y13,"") -> 0.855991 | AA13: =IF(AND(ISNUMBER(J13),ISNUMBER(B13),B13>0),(J13-B13)/B13,"") -> 0.012048193 | AB13: =IF(AND(ISNUMBER(L13),ISNUMBER(B13),B13>0),(B13-L13)/B13,"") -> 0.012048193 | AC13: =IF(AND(ISNUMBER(J13),ISNUMBER(L13)),J13-L13,"") -> 1.5 | AD13: =IF(AND(ISNUMBER(Y13),Y13>0.05,ISNUMBER(AA13),AA13>0.015,ISNUMBER(AB13),AB13>0.015,ISNUMBER(W13),W13<0.5,ISNUMBER(X13),X13<0.5,ISNUMBER(AC13),AC13>0,ISNUMBER(F13),F13>=2),"✅ YES","🚫 NO") -> 🚫 NO | AE13: =_xldudf_optionsamurai_option(A13,"CALL",$B$3,"25d","strike") -> 68 | AF13: =_xldudf_optionsamurai_option(A13,"CALL",$B$3,"25d","bid") -> N/A | AG13: =_xldudf_optionsamurai_option(A13,"PUT",$B$3,"25d","strike") -> 59 | AH13: =_xldudf_optionsamurai_option(A13,"PUT",$B$3,"25d","bid") -> N/A | AI13: =_xldudf_optionsamurai_option(A13,"CALL",$B$3,TEXT(J13,"0"),"prob_otm") -> 0.588484 | AJ13: =_xldudf_optionsamurai_option(A13,"PUT",$B$3,TEXT(L13,"0"),"prob_otm") -> 0.532769 | AK13: =IF(AND(ISNUMBER(AI13),ISNUMBER(AJ13)),AI13*AJ13,"") -> 0.31352603 | AL13: =_xldudf_optionsamurai_stock(A13,"stock_iv_rv_pr") -> 0.119048 | AM13: =_xldudf_optionsamurai_stock(A13,"atr_percent") -> 0.020723 | AN13: =_xldudf_optionsamurai_stock(A13,"short_ratio") -> 1.81 | AO13: =IF(ISNUMBER(AL13),IF(AL13>=0.6,"🟢 IV>RV",IF(AL13>=0.3,"🟡 Moderate","🔴 IV<RV")),"") -> 🔴 IV<RV | AP13: =IF(ISNUMBER(AM13),IF(AM13<=0.02,"🟢 Smooth",IF(AM13<=0.04,"🟡 Moderate","🔴 Choppy")),"") -> 🟡 Moderate | AS13: =IF(ISNUMBER(AQ13),MAX(0,B13-J13),"") | AT13: =IF(ISNUMBER(AR13),MAX(0,L13-B13),"") | AU13: =IF(AND(ISNUMBER(AQ13),ISNUMBER(AR13)),(AQ13+AR13-IF(ISNUMBER(AS13),AS13,0)-IF(ISNUMBER(AT13),AT13,0))*100,"")
A14: ETHA | B14: =_xldudf_optionsamurai_stock(A14,"stock_last") -> 17.35 | C14: =_xldudf_optionsamurai_stock(A14,"stock_iv") -> 0.6292 | D14: =_xldudf_optionsamurai_stock(A14,"sector") -> Financial | E14: =_xldudf_optionsamurai_stock(A14,"industry") -> Exchange Traded Fund | F14: =IF(AND(ISNUMBER(_xldudf_optionsamurai_stock(A14,"sma_50d")),ISNUMBER(_xldudf_optionsamurai_stock(A14,"sma_200d")),ISNUMBER(_xldudf_optionsamurai_stock(A14,"perf_m")),ISNUMBER(_xldudf_optionsamurai_stock(A14,"perf_q"))),(_xldudf_optionsamurai_stock(A14,"sma_50d")>0)*1+(_xldudf_optionsamurai_stock(A14,"sma_200d")>0)*1+(_xldudf_optionsamurai_stock(A14,"perf_m")>0)*1+(_xldudf_optionsamurai_stock(A14,"perf_q")>0)*1,"") -> 2 | G14: =IF(ISNUMBER(_xldudf_optionsamurai_stock(A14,"sma_50d")),"50d:"&TEXT(_xldudf_optionsamurai_stock(A14,"sma_50d"),"0.0%")&" 200d:"&TEXT(_xldudf_optionsamurai_stock(A14,"sma_200d"),"0.0%")&" 1m:"&TEXT(_xldudf_optionsamurai_stock(A14,"perf_m"),"0.0%")&" 3m:"&TEXT(_xldudf_optionsamurai_stock(A14,"perf_q"),"0.0%"),"") -> 50d:8.9% 200d:-28.6% 1m:7.8% 3m:-23.5% | H14: =_xldudf_optionsamurai_stock(A14,"perf_m") -> 0.0776 | I14: =_xldudf_optionsamurai_stock(A14,"perf_q") -> -0.2347 | J14: =_xldudf_optionsamurai_option(A14,"CALL",$B$3,"1.5%","strike") -> 17.5 | K14: =_xldudf_optionsamurai_option(A14,"CALL",$B$3,"1.5%","bid") -> 0.87 | L14: =_xldudf_optionsamurai_option(A14,"PUT",$B$3,"-1.5%","strike") -> 17 | M14: =_xldudf_optionsamurai_option(A14,"PUT",$B$3,"-1.5%","bid") -> 0.75 | N14: =K14+M14 -> 1.62 | O14: =IF(B14>0,N14/B14,"") -> 0.093371758 | P14: =_xldudf_optionsamurai_option(A14,"CALL",$B$3,"1.5%","strike") -> 17.5 | Q14: =_xldudf_optionsamurai_option(A14,"CALL",$B$3,"1.5%","bid") -> 0.87 | R14: =IF(B14>0,Q14/B14,"") -> 0.050144092 | S14: =_xldudf_optionsamurai_option(A14,"PUT",$B$3,"-1.5%","strike") -> 17 | T14: =_xldudf_optionsamurai_option(A14,"PUT",$B$3,"-1.5%","bid") -> 0.75 | U14: =IF(B14>0,T14/B14,"") -> 0.043227666 | V14: =_xldudf_optionsamurai_stock(A14,"earnings_date") -> N/A | W14: =_xldudf_optionsamurai_option(A14,"CALL",$B$3,"1.5%","delta") -> 0.506727 | X14: =ABS(_xldudf_optionsamurai_option(A14,"PUT",$B$3,"-1.5%","delta")) -> 0.409513 | Y14: =IF(AND(ISNUMBER(W14),ISNUMBER(X14)),1-W14-X14,"") -> 0.08376 | Z14: =IF(ISNUMBER(Y14),1-Y14,"") -> 0.91624 | AA14: =IF(AND(ISNUMBER(J14),ISNUMBER(B14),B14>0),(J14-B14)/B14,"") -> 0.0086455331 | AB14: =IF(AND(ISNUMBER(L14),ISNUMBER(B14),B14>0),(B14-L14)/B14,"") -> 0.020172911 | AC14: =IF(AND(ISNUMBER(J14),ISNUMBER(L14)),J14-L14,"") -> 0.5 | AD14: =IF(AND(ISNUMBER(Y14),Y14>0.05,ISNUMBER(AA14),AA14>0.015,ISNUMBER(AB14),AB14>0.015,ISNUMBER(W14),W14<0.5,ISNUMBER(X14),X14<0.5,ISNUMBER(AC14),AC14>0,ISNUMBER(F14),F14>=2),"✅ YES","🚫 NO") -> 🚫 NO | AE14: =_xldudf_optionsamurai_option(A14,"CALL",$B$3,"25d","strike") -> 19 | AF14: =_xldudf_optionsamurai_option(A14,"CALL",$B$3,"25d","bid") -> 0.35 | AG14: =_xldudf_optionsamurai_option(A14,"PUT",$B$3,"25d","strike") -> 16 | AH14: =_xldudf_optionsamurai_option(A14,"PUT",$B$3,"25d","bid") -> 0.41 | AI14: =_xldudf_optionsamurai_option(A14,"CALL",$B$3,TEXT(J14,"0"),"prob_otm") -> 0.628689 | AJ14: =_xldudf_optionsamurai_option(A14,"PUT",$B$3,TEXT(L14,"0"),"prob_otm") -> 0.5384 | AK14: =IF(AND(ISNUMBER(AI14),ISNUMBER(AJ14)),AI14*AJ14,"") -> 0.33848616 | AL14: =_xldudf_optionsamurai_stock(A14,"stock_iv_rv_pr") -> 0.873016 | AM14: =_xldudf_optionsamurai_stock(A14,"atr_percent") -> 0.04438 | AN14: =_xldudf_optionsamurai_stock(A14,"short_ratio") -> 0.39 | AO14: =IF(ISNUMBER(AL14),IF(AL14>=0.6,"🟢 IV>RV",IF(AL14>=0.3,"🟡 Moderate","🔴 IV<RV")),"") -> 🟢 IV>RV | AP14: =IF(ISNUMBER(AM14),IF(AM14<=0.02,"🟢 Smooth",IF(AM14<=0.04,"🟡 Moderate","🔴 Choppy")),"") -> 🔴 Choppy | AS14: =IF(ISNUMBER(AQ14),MAX(0,B14-J14),"") | AT14: =IF(ISNUMBER(AR14),MAX(0,L14-B14),"") | AU14: =IF(AND(ISNUMBER(AQ14),ISNUMBER(AR14)),(AQ14+AR14-IF(ISNUMBER(AS14),AS14,0)-IF(ISNUMBER(AT14),AT14,0))*100,"")
A15: EWJ | B15: =_xldudf_optionsamurai_stock(A15,"stock_last") -> 87.14 | C15: =_xldudf_optionsamurai_stock(A15,"stock_iv") -> 0.2391 | D15: =_xldudf_optionsamurai_stock(A15,"sector") -> Financial | E15: =_xldudf_optionsamurai_stock(A15,"industry") -> Exchange Traded Fund | F15: =IF(AND(ISNUMBER(_xldudf_optionsamurai_stock(A15,"sma_50d")),ISNUMBER(_xldudf_optionsamurai_stock(A15,"sma_200d")),ISNUMBER(_xldudf_optionsamurai_stock(A15,"perf_m")),ISNUMBER(_xldudf_optionsamurai_stock(A15,"perf_q"))),(_xldudf_optionsamurai_stock(A15,"sma_50d")>0)*1+(_xldudf_optionsamurai_stock(A15,"sma_200d")>0)*1+(_xldudf_optionsamurai_stock(A15,"perf_m")>0)*1+(_xldudf_optionsamurai_stock(A15,"perf_q")>0)*1,"") -> 3 | G15: =IF(ISNUMBER(_xldudf_optionsamurai_stock(A15,"sma_50d")),"50d:"&TEXT(_xldudf_optionsamurai_stock(A15,"sma_50d"),"0.0%")&" 200d:"&TEXT(_xldudf_optionsamurai_stock(A15,"sma_200d"),"0.0%")&" 1m:"&TEXT(_xldudf_optionsamurai_stock(A15,"perf_m"),"0.0%")&" 3m:"&TEXT(_xldudf_optionsamurai_stock(A15,"perf_q"),"0.0%"),"") -> 50d:-0.7% 200d:5.8% 1m:7.3% 3m:4.1% | H15: =_xldudf_optionsamurai_stock(A15,"perf_m") -> 0.0732 | I15: =_xldudf_optionsamurai_stock(A15,"perf_q") -> 0.0409 | J15: =_xldudf_optionsamurai_option(A15,"CALL",$B$3,"1.5%","strike") -> 88.5 | K15: =_xldudf_optionsamurai_option(A15,"CALL",$B$3,"1.5%","bid") -> 1.1 | L15: =_xldudf_optionsamurai_option(A15,"PUT",$B$3,"-1.5%","strike") -> 86 | M15: =_xldudf_optionsamurai_option(A15,"PUT",$B$3,"-1.5%","bid") -> 1.15 | N15: =K15+M15 -> 2.25 | O15: =IF(B15>0,N15/B15,"") -> 0.025820519 | P15: =_xldudf_optionsamurai_option(A15,"CALL",$B$3,"1.5%","strike") -> 88.5 | Q15: =_xldudf_optionsamurai_option(A15,"CALL",$B$3,"1.5%","bid") -> 1.1 | R15: =IF(B15>0,Q15/B15,"") -> 0.012623365 | S15: =_xldudf_optionsamurai_option(A15,"PUT",$B$3,"-1.5%","strike") -> 86 | T15: =_xldudf_optionsamurai_option(A15,"PUT",$B$3,"-1.5%","bid") -> 1.15 | U15: =IF(B15>0,T15/B15,"") -> 0.013197154 | V15: =_xldudf_optionsamurai_stock(A15,"earnings_date") -> N/A | W15: =_xldudf_optionsamurai_option(A15,"CALL",$B$3,"1.5%","delta") -> 0.413967 | X15: =ABS(_xldudf_optionsamurai_option(A15,"PUT",$B$3,"-1.5%","delta")) -> 0.392263 | Y15: =IF(AND(ISNUMBER(W15),ISNUMBER(X15)),1-W15-X15,"") -> 0.19377 | Z15: =IF(ISNUMBER(Y15),1-Y15,"") -> 0.80623 | AA15: =IF(AND(ISNUMBER(J15),ISNUMBER(B15),B15>0),(J15-B15)/B15,"") -> 0.015607069 | AB15: =IF(AND(ISNUMBER(L15),ISNUMBER(B15),B15>0),(B15-L15)/B15,"") -> 0.013082396 | AC15: =IF(AND(ISNUMBER(J15),ISNUMBER(L15)),J15-L15,"") -> 2.5 | AD15: =IF(AND(ISNUMBER(Y15),Y15>0.05,ISNUMBER(AA15),AA15>0.015,ISNUMBER(AB15),AB15>0.015,ISNUMBER(W15),W15<0.5,ISNUMBER(X15),X15<0.5,ISNUMBER(AC15),AC15>0,ISNUMBER(F15),F15>=2),"✅ YES","🚫 NO") -> 🚫 NO | AE15: =_xldudf_optionsamurai_option(A15,"CALL",$B$3,"25d","strike") -> 92 | AF15: =_xldudf_optionsamurai_option(A15,"CALL",$B$3,"25d","bid") -> 0.05 | AG15: =_xldudf_optionsamurai_option(A15,"PUT",$B$3,"25d","strike") -> 83.5 | AH15: =_xldudf_optionsamurai_option(A15,"PUT",$B$3,"25d","bid") -> 0.55 | AI15: =_xldudf_optionsamurai_option(A15,"CALL",$B$3,TEXT(J15,"0"),"prob_otm") -> 0.657808 | AJ15: =_xldudf_optionsamurai_option(A15,"PUT",$B$3,TEXT(L15,"0"),"prob_otm") -> 0.604182 | AK15: =IF(AND(ISNUMBER(AI15),ISNUMBER(AJ15)),AI15*AJ15,"") -> 0.39743575 | AL15: =_xldudf_optionsamurai_stock(A15,"stock_iv_rv_pr") -> 0.154762 | AM15: =_xldudf_optionsamurai_stock(A15,"atr_percent") -> 0.020771 | AN15: =_xldudf_optionsamurai_stock(A15,"short_ratio") -> 1.99 | AO15: =IF(ISNUMBER(AL15),IF(AL15>=0.6,"🟢 IV>RV",IF(AL15>=0.3,"🟡 Moderate","🔴 IV<RV")),"") -> 🔴 IV<RV | AP15: =IF(ISNUMBER(AM15),IF(AM15<=0.02,"🟢 Smooth",IF(AM15<=0.04,"🟡 Moderate","🔴 Choppy")),"") -> 🟡 Moderate | AS15: =IF(ISNUMBER(AQ15),MAX(0,B15-J15),"") | AT15: =IF(ISNUMBER(AR15),MAX(0,L15-B15),"") | AU15: =IF(AND(ISNUMBER(AQ15),ISNUMBER(AR15)),(AQ15+AR15-IF(ISNUMBER(AS15),AS15,0)-IF(ISNUMBER(AT15),AT15,0))*100,"")
A16: EWZ | B16: =_xldudf_optionsamurai_stock(A16,"stock_last") -> 40.79 | C16: =_xldudf_optionsamurai_stock(A16,"stock_iv") -> 0.2892 | D16: =_xldudf_optionsamurai_stock(A16,"sector") -> Financial | E16: =_xldudf_optionsamurai_stock(A16,"industry") -> Exchange Traded Fund | F16: =IF(AND(ISNUMBER(_xldudf_optionsamurai_stock(A16,"sma_50d")),ISNUMBER(_xldudf_optionsamurai_stock(A16,"sma_200d")),ISNUMBER(_xldudf_optionsamurai_stock(A16,"perf_m")),ISNUMBER(_xldudf_optionsamurai_stock(A16,"perf_q"))),(_xldudf_optionsamurai_stock(A16,"sma_50d")>0)*1+(_xldudf_optionsamurai_stock(A16,"sma_200d")>0)*1+(_xldudf_optionsamurai_stock(A16,"perf_m")>0)*1+(_xldudf_optionsamurai_stock(A16,"perf_q")>0)*1,"") -> 4 | G16: =IF(ISNUMBER(_xldudf_optionsamurai_stock(A16,"sma_50d")),"50d:"&TEXT(_xldudf_optionsamurai_stock(A16,"sma_50d"),"0.0%")&" 200d:"&TEXT(_xldudf_optionsamurai_stock(A16,"sma_200d"),"0.0%")&" 1m:"&TEXT(_xldudf_optionsamurai_stock(A16,"perf_m"),"0.0%")&" 3m:"&TEXT(_xldudf_optionsamurai_stock(A16,"perf_q"),"0.0%"),"") -> 50d:6.4% 200d:24.5% 1m:16.3% 3m:21.3% | H16: =_xldudf_optionsamurai_stock(A16,"perf_m") -> 0.1634 | I16: =_xldudf_optionsamurai_stock(A16,"perf_q") -> 0.2133 | J16: =_xldudf_optionsamurai_option(A16,"CALL",$B$3,"1.5%","strike") -> 41.5 | K16: =_xldudf_optionsamurai_option(A16,"CALL",$B$3,"1.5%","bid") -> 0.6 | L16: =_xldudf_optionsamurai_option(A16,"PUT",$B$3,"-1.5%","strike") -> 40 | M16: =_xldudf_optionsamurai_option(A16,"PUT",$B$3,"-1.5%","bid") -> 0.4 | N16: =K16+M16 -> 1 | O16: =IF(B16>0,N16/B16,"") -> 0.024515813 | P16: =_xldudf_optionsamurai_option(A16,"CALL",$B$3,"1.5%","strike") -> 41.5 | Q16: =_xldudf_optionsamurai_option(A16,"CALL",$B$3,"1.5%","bid") -> 0.6 | R16: =IF(B16>0,Q16/B16,"") -> 0.014709488 | S16: =_xldudf_optionsamurai_option(A16,"PUT",$B$3,"-1.5%","strike") -> 40 | T16: =_xldudf_optionsamurai_option(A16,"PUT",$B$3,"-1.5%","bid") -> 0.4 | U16: =IF(B16>0,T16/B16,"") -> 0.0098063251 | V16: =_xldudf_optionsamurai_stock(A16,"earnings_date") -> N/A | W16: =_xldudf_optionsamurai_option(A16,"CALL",$B$3,"1.5%","delta") -> 0.436098 | X16: =ABS(_xldudf_optionsamurai_option(A16,"PUT",$B$3,"-1.5%","delta")) -> 0.361142 | Y16: =IF(AND(ISNUMBER(W16),ISNUMBER(X16)),1-W16-X16,"") -> 0.20276 | Z16: =IF(ISNUMBER(Y16),1-Y16,"") -> 0.79724 | AA16: =IF(AND(ISNUMBER(J16),ISNUMBER(B16),B16>0),(J16-B16)/B16,"") -> 0.017406227 | AB16: =IF(AND(ISNUMBER(L16),ISNUMBER(B16),B16>0),(B16-L16)/B16,"") -> 0.019367492 | AC16: =IF(AND(ISNUMBER(J16),ISNUMBER(L16)),J16-L16,"") -> 1.5 | AD16: =IF(AND(ISNUMBER(Y16),Y16>0.05,ISNUMBER(AA16),AA16>0.015,ISNUMBER(AB16),AB16>0.015,ISNUMBER(W16),W16<0.5,ISNUMBER(X16),X16<0.5,ISNUMBER(AC16),AC16>0,ISNUMBER(F16),F16>=2),"✅ YES","🚫 NO") -> ✅ YES | AE16: =_xldudf_optionsamurai_option(A16,"CALL",$B$3,"25d","strike") -> 48 | AF16: =_xldudf_optionsamurai_option(A16,"CALL",$B$3,"25d","bid") -> N/A | AG16: =_xldudf_optionsamurai_option(A16,"PUT",$B$3,"25d","strike") -> 39.5 | AH16: =_xldudf_optionsamurai_option(A16,"PUT",$B$3,"25d","bid") -> 0.25 | AI16: =_xldudf_optionsamurai_option(A16,"CALL",$B$3,TEXT(J16,"0"),"prob_otm") -> 0.683316 | AJ16: =_xldudf_optionsamurai_option(A16,"PUT",$B$3,TEXT(L16,"0"),"prob_otm") -> 0.622448 | AK16: =IF(AND(ISNUMBER(AI16),ISNUMBER(AJ16)),AI16*AJ16,"") -> 0.42532868 | AL16: =_xldudf_optionsamurai_stock(A16,"stock_iv_rv_pr") -> 0.174603 | AM16: =_xldudf_optionsamurai_stock(A16,"atr_percent") -> 0.021329 | AN16: =_xldudf_optionsamurai_stock(A16,"short_ratio") -> 1.36 | AO16: =IF(ISNUMBER(AL16),IF(AL16>=0.6,"🟢 IV>RV",IF(AL16>=0.3,"🟡 Moderate","🔴 IV<RV")),"") -> 🔴 IV<RV | AP16: =IF(ISNUMBER(AM16),IF(AM16<=0.02,"🟢 Smooth",IF(AM16<=0.04,"🟡 Moderate","🔴 Choppy")),"") -> 🟡 Moderate | AS16: =IF(ISNUMBER(AQ16),MAX(0,B16-J16),"") | AT16: =IF(ISNUMBER(AR16),MAX(0,L16-B16),"") | AU16: =IF(AND(ISNUMBER(AQ16),ISNUMBER(AR16)),(AQ16+AR16-IF(ISNUMBER(AS16),AS16,0)-IF(ISNUMBER(AT16),AT16,0))*100,"")
A17: IAU | B17: =_xldudf_optionsamurai_stock(A17,"stock_last") -> 88.04 | C17: =_xldudf_optionsamurai_stock(A17,"stock_iv") -> 0.2536 | D17: =_xldudf_optionsamurai_stock(A17,"sector") -> Financial | E17: =_xldudf_optionsamurai_stock(A17,"industry") -> Exchange Traded Fund | F17: =IF(AND(ISNUMBER(_xldudf_optionsamurai_stock(A17,"sma_50d")),ISNUMBER(_xldudf_optionsamurai_stock(A17,"sma_200d")),ISNUMBER(_xldudf_optionsamurai_stock(A17,"perf_m")),ISNUMBER(_xldudf_optionsamurai_stock(A17,"perf_q"))),(_xldudf_optionsamurai_stock(A17,"sma_50d")>0)*1+(_xldudf_optionsamurai_stock(A17,"sma_200d")>0)*1+(_xldudf_optionsamurai_stock(A17,"perf_m")>0)*1+(_xldudf_optionsamurai_stock(A17,"perf_q")>0)*1,"") -> 2 | G17: =IF(ISNUMBER(_xldudf_optionsamurai_stock(A17,"sma_50d")),"50d:"&TEXT(_xldudf_optionsamurai_stock(A17,"sma_50d"),"0.0%")&" 200d:"&TEXT(_xldudf_optionsamurai_stock(A17,"sma_200d"),"0.0%")&" 1m:"&TEXT(_xldudf_optionsamurai_stock(A17,"perf_m"),"0.0%")&" 3m:"&TEXT(_xldudf_optionsamurai_stock(A17,"perf_q"),"0.0%"),"") -> 50d:-4.3% 200d:11.2% 1m:3.9% 3m:-1.7% | H17: =_xldudf_optionsamurai_stock(A17,"perf_m") -> 0.0394 | I17: =_xldudf_optionsamurai_stock(A17,"perf_q") -> -0.0169 | J17: =_xldudf_optionsamurai_option(A17,"CALL",$B$3,"1.5%","strike") -> 89.5 | K17: =_xldudf_optionsamurai_option(A17,"CALL",$B$3,"1.5%","bid") -> 1.2 | L17: =_xldudf_optionsamurai_option(A17,"PUT",$B$3,"-1.5%","strike") -> 86.5 | M17: =_xldudf_optionsamurai_option(A17,"PUT",$B$3,"-1.5%","bid") -> 1.1 | N17: =K17+M17 -> 2.3 | O17: =IF(B17>0,N17/B17,"") -> 0.026124489 | P17: =_xldudf_optionsamurai_option(A17,"CALL",$B$3,"1.5%","strike") -> 89.5 | Q17: =_xldudf_optionsamurai_option(A17,"CALL",$B$3,"1.5%","bid") -> 1.2 | R17: =IF(B17>0,Q17/B17,"") -> 0.013630168 | S17: =_xldudf_optionsamurai_option(A17,"PUT",$B$3,"-1.5%","strike") -> 86.5 | T17: =_xldudf_optionsamurai_option(A17,"PUT",$B$3,"-1.5%","bid") -> 1.1 | U17: =IF(B17>0,T17/B17,"") -> 0.012494321 | V17: =_xldudf_optionsamurai_stock(A17,"earnings_date") -> N/A | W17: =_xldudf_optionsamurai_option(A17,"CALL",$B$3,"1.5%","delta") -> 0.412594 | X17: =ABS(_xldudf_optionsamurai_option(A17,"PUT",$B$3,"-1.5%","delta")) -> 0.368911 | Y17: =IF(AND(ISNUMBER(W17),ISNUMBER(X17)),1-W17-X17,"") -> 0.218495 | Z17: =IF(ISNUMBER(Y17),1-Y17,"") -> 0.781505 | AA17: =IF(AND(ISNUMBER(J17),ISNUMBER(B17),B17>0),(J17-B17)/B17,"") -> 0.016583371 | AB17: =IF(AND(ISNUMBER(L17),ISNUMBER(B17),B17>0),(B17-L17)/B17,"") -> 0.017492049 | AC17: =IF(AND(ISNUMBER(J17),ISNUMBER(L17)),J17-L17,"") -> 3 | AD17: =IF(AND(ISNUMBER(Y17),Y17>0.05,ISNUMBER(AA17),AA17>0.015,ISNUMBER(AB17),AB17>0.015,ISNUMBER(W17),W17<0.5,ISNUMBER(X17),X17<0.5,ISNUMBER(AC17),AC17>0,ISNUMBER(F17),F17>=2),"✅ YES","🚫 NO") -> ✅ YES | AE17: =_xldudf_optionsamurai_option(A17,"CALL",$B$3,"25d","strike") -> 92 | AF17: =_xldudf_optionsamurai_option(A17,"CALL",$B$3,"25d","bid") -> 0.5 | AG17: =_xldudf_optionsamurai_option(A17,"PUT",$B$3,"25d","strike") -> 85 | AH17: =_xldudf_optionsamurai_option(A17,"PUT",$B$3,"25d","bid") -> 0.55 | AI17: =_xldudf_optionsamurai_option(A17,"CALL",$B$3,TEXT(J17,"0"),"prob_otm") -> 0.656476 | AJ17: =_xldudf_optionsamurai_option(A17,"PUT",$B$3,TEXT(L17,"0"),"prob_otm") -> 0.587993 | AK17: =IF(AND(ISNUMBER(AI17),ISNUMBER(AJ17)),AI17*AJ17,"") -> 0.38600329 | AL17: =_xldudf_optionsamurai_stock(A17,"stock_iv_rv_pr") -> 0.289683 | AM17: =_xldudf_optionsamurai_stock(A17,"atr_percent") -> 0.022603 | AN17: =_xldudf_optionsamurai_stock(A17,"short_ratio") -> 0.66 | AO17: =IF(ISNUMBER(AL17),IF(AL17>=0.6,"🟢 IV>RV",IF(AL17>=0.3,"🟡 Moderate","🔴 IV<RV")),"") -> 🔴 IV<RV | AP17: =IF(ISNUMBER(AM17),IF(AM17<=0.02,"🟢 Smooth",IF(AM17<=0.04,"🟡 Moderate","🔴 Choppy")),"") -> 🟡 Moderate | AS17: =IF(ISNUMBER(AQ17),MAX(0,B17-J17),"") | AT17: =IF(ISNUMBER(AR17),MAX(0,L17-B17),"") | AU17: =IF(AND(ISNUMBER(AQ17),ISNUMBER(AR17)),(AQ17+AR17-IF(ISNUMBER(AS17),AS17,0)-IF(ISNUMBER(AT17),AT17,0))*100,"")
... A25: RNG | B25: =_xldudf_optionsamurai_stock(A25,"stock_last") -> 41.34 | C25: =_xldudf_optionsamurai_stock(A25,"stock_iv") -> 0.7789 | D25: =_xldudf_optionsamurai_stock(A25,"sector") -> Technology | E25: =_xldudf_optionsamurai_stock(A25,"industry") -> Software - Application | F25: =IF(AND(ISNUMBER(_xldudf_optionsamurai_stock(A25,"sma_50d")),ISNUMBER(_xldudf_optionsamurai_stock(A25,"sma_200d")),ISNUMBER(_xldudf_optionsamurai_stock(A25,"perf_m")),ISNUMBER(_xldudf_optionsamurai_stock(A25,"perf_q"))),(_xldudf_optionsamurai_stock(A25,"sma_50d")>0)*1+(_xldudf_optionsamurai_stock(A25,"sma_200d")>0)*1+(_xldudf_optionsamurai_stock(A25,"perf_m")>0)*1+(_xldudf_optionsamurai_stock(A25,"perf_q")>0)*1,"") -> 4 | G25: =IF(ISNUMBER(_xldudf_optionsamurai_stock(A25,"sma_50d")),"50d:"&TEXT(_xldudf_optionsamurai_stock(A25,"sma_50d"),"0.0%")&" 200d:"&TEXT(_xldudf_optionsamurai_stock(A25,"sma_200d"),"0.0%")&" 1m:"&TEXT(_xldudf_optionsamurai_stock(A25,"perf_m"),"0.0%")&" 3m:"&TEXT(_xldudf_optionsamurai_stock(A25,"perf_q"),"0.0%"),"") -> 50d:13.6% 200d:35.6% 1m:9.9% 3m:60.2% | H25: =_xldudf_optionsamurai_stock(A25,"perf_m") -> 0.0986 | I25: =_xldudf_optionsamurai_stock(A25,"perf_q") -> 0.6017 | J25: =_xldudf_optionsamurai_option(A25,"CALL",$B$3,"1.5%","strike") -> 42 | K25: =_xldudf_optionsamurai_option(A25,"CALL",$B$3,"1.5%","bid") -> 2.65 | L25: =_xldudf_optionsamurai_option(A25,"PUT",$B$3,"-1.5%","strike") -> 41 | M25: =_xldudf_optionsamurai_option(A25,"PUT",$B$3,"-1.5%","bid") -> 2.75 | N25: =K25+M25 -> 5.4 | O25: =IF(B25>0,N25/B25,"") -> 0.13062409 | P25: =_xldudf_optionsamurai_option(A25,"CALL",$B$3,"1.5%","strike") -> 42 | Q25: =_xldudf_optionsamurai_option(A25,"CALL",$B$3,"1.5%","bid") -> 2.65 | R25: =IF(B25>0,Q25/B25,"") -> 0.064102564 | S25: =_xldudf_optionsamurai_option(A25,"PUT",$B$3,"-1.5%","strike") -> 41 | T25: =_xldudf_optionsamurai_option(A25,"PUT",$B$3,"-1.5%","bid") -> 2.75 | U25: =IF(B25>0,T25/B25,"") -> 0.066521529 | V25: =_xldudf_optionsamurai_stock(A25,"earnings_date") -> 2026-05-07 | W25: =_xldudf_optionsamurai_option(A25,"CALL",$B$3,"1.5%","delta") -> 0.513533 | X25: =ABS(_xldudf_optionsamurai_option(A25,"PUT",$B$3,"-1.5%","delta")) -> 0.439959 | Y25: =IF(AND(ISNUMBER(W25),ISNUMBER(X25)),1-W25-X25,"") -> 0.046508 | Z25: =IF(ISNUMBER(Y25),1-Y25,"") -> 0.953492 | AA25: =IF(AND(ISNUMBER(J25),ISNUMBER(B25),B25>0),(J25-B25)/B25,"") -> 0.015965167 | AB25: =IF(AND(ISNUMBER(L25),ISNUMBER(B25),B25>0),(B25-L25)/B25,"") -> 0.0082244799 | AC25: =IF(AND(ISNUMBER(J25),ISNUMBER(L25)),J25-L25,"") -> 1 | AD25: =IF(AND(ISNUMBER(Y25),Y25>0.05,ISNUMBER(AA25),AA25>0.015,ISNUMBER(AB25),AB25>0.015,ISNUMBER(W25),W25<0.5,ISNUMBER(X25),X25<0.5,ISNUMBER(AC25),AC25>0,ISNUMBER(F25),F25>=2),"✅ YES","🚫 NO") -> 🚫 NO | AE25: =_xldudf_optionsamurai_option(A25,"CALL",$B$3,"25d","strike") -> 49 | AF25: =_xldudf_optionsamurai_option(A25,"CALL",$B$3,"25d","bid") -> 0.7 | AG25: =_xldudf_optionsamurai_option(A25,"PUT",$B$3,"25d","strike") -> 37 | AH25: =_xldudf_optionsamurai_option(A25,"PUT",$B$3,"25d","bid") -> 1.05 | AI25: =_xldudf_optionsamurai_option(A25,"CALL",$B$3,TEXT(J25,"0"),"prob_otm") -> 0.566906 | AJ25: =_xldudf_optionsamurai_option(A25,"PUT",$B$3,TEXT(L25,"0"),"prob_otm") -> 0.490513 | AK25: =IF(AND(ISNUMBER(AI25),ISNUMBER(AJ25)),AI25*AJ25,"") -> 0.27807476 | AL25: =_xldudf_optionsamurai_stock(A25,"stock_iv_rv_pr") -> 0.880952 | AM25: =_xldudf_optionsamurai_stock(A25,"atr_percent") -> 0.054185 | AN25: =_xldudf_optionsamurai_stock(A25,"short_ratio") -> 3.25 | AO25: =IF(ISNUMBER(AL25),IF(AL25>=0.6,"🟢 IV>RV",IF(AL25>=0.3,"🟡 Moderate","🔴 IV<RV")),"") -> 🟢 IV>RV | AP25: =IF(ISNUMBER(AM25),IF(AM25<=0.02,"🟢 Smooth",IF(AM25<=0.04,"🟡 Moderate","🔴 Choppy")),"") -> 🔴 Choppy | AS25: =IF(ISNUMBER(AQ25),MAX(0,B25-J25),"") | AT25: =IF(ISNUMBER(AR25),MAX(0,L25-B25),"") | AU25: =IF(AND(ISNUMBER(AQ25),ISNUMBER(AR25)),(AQ25+AR25-IF(ISNUMBER(AS25),AS25,0)-IF(ISNUMBER(AT25),AT25,0))*100,"")
A27: ⚠ TRADE? (AD) requires ALL 7: Prob Profit >5% | Call dist 1.5–4% | Put dist 1.5–4% | Call Δ <0.50 | Put Δ <0.50 | Strikes differ | MA Count F≥2 || MA Count (F): 4 indicators — 50d MA dist, 200d MA dist, 1m Perf, 3m Perf. 🟢 4/4 ✅ 3/4 ✅ 2/4 = PASS ⛔ 1 or 0 = FAIL || Stock IV: 🟢 <40% 🟡 40–80% 🔴 >80% || Prob OTM: 🟢 >60% 🟡 40–60% 🔴 <40% || Prob Both Worthless (AK): 🟢 >40% 🟡 25–40% 🔴 <25% || Advisory — IV-RV Pct (AL): 🟢 ≥60% 🟡 30–60% 🔴 <30% || ATR% (AM): 🟢 ≤2% 🟡 2–4% 🔴 >4% || Short Ratio (AN): 🟢 <3 🟡 3–10 🔴 >10 || ⚠️ P&L cols AQ/AR: enter actual bids in YELLOW cells when trade opens. AS/AT/AU auto-calculate intrinsic value and open P&L. Clear AQ/AR on close.

Sheet Bull Strangle - News Letter
A1: Bull Strangle Newsletter — Watch List: April 13, 2026 Entry / May 8, 2026 Expiration
A2: Source: Dual Edge Research — Darren Carlat | All prices from Friday April 10, 2026 close
A3: Stock / ETF | D3: Implied Vol | E3: Sector | F3: Sell Call Option | H3: Sell Put Option | J3: Bull Strangle Return | K3: Put Credit Spread | L3: Covered Call
A4: Symbol | B4: Description | C4: Last Price | D4: Impl Vol | E4: Sector | F4: Call Strike | G4: Call Bid | H4: Put Strike | I4: Put Bid | J4: Bull Strangle | K4: Put Credit Spread | L4: Covered Call
A5: PSKY | B5: Paramount Skydance Corp Cl B | C5: 10.62 | D5: 0.5939 | E5: Communication Services | F5: 11 | G5: 0.42 | H5: 10 | I5: 1 | J5: 0.134 | K5: 0.094 | L5: 0.04
A6: DECK | B6: Deckers Outdoor Corp | C6: 107.86 | D6: 0.3896 | E6: Consumer Discretionary | F6: 110 | G6: 3.4 | H6: 106 | I6: 3 | J6: 0.059 | K6: 0.028 | L6: 0.032
A7: GME | B7: Gamestop Corp | C7: 23.22 | D7: 0.3505 | E7: Consumer Discretionary | F7: 24 | G7: 0.35 | H7: 22.5 | I7: 0.44 | J7: 0.034 | K7: 0.019 | L7: 0.015
A8: JD | B8: Jd.com Inc ADR | C8: 28.93 | D8: 0.4069 | E8: Consumer Discretionary | F8: 30 | G8: 0.73 | H8: 28 | I8: 0.67 | J8: 0.048 | K8: 0.023 | L8: 0.025
A9: URBN | B9: Urban Outfitters Inc | C9: 68.6 | D9: 0.4273 | E9: Consumer Discretionary | F9: 70 | G9: 2.3 | H9: 67 | I9: 2.3 | J9: 0.067 | K9: 0.034 | L9: 0.034
A10: BUD | B10: Anheuser-Busch Inbev S.A. ADR | C10: 75.73 | D10: 0.2977 | E10: Consumer Staples | F10: 77 | G10: 1.5 | H10: 74 | I10: 1.45 | J10: 0.039 | K10: 0.019 | L10: 0.02
A11: UEC | B11: Uranium Energy Corp | C11: 13.53 | D11: 0.7953 | E11: Energy | F11: 14 | G11: 0.95 | H11: 13 | I11: 0.88 | J11: 0.135 | K11: 0.065 | L11: 0.07
A12: EEM | B12: Emrg Mkts iShares MSCI ETF | C12: 60.56 | D12: 0.2719 | E12: ETF | F12: 61.5 | G12: 1.19 | H12: 59.5 | I12: 1.12 | J12: 0.038 | K12: 0.018 | L12: 0.02
A13: ETHA | B13: iShares Ethereum Trust ETF | C13: 17.05 | D13: 0.6231 | E13: ETF | F13: 17.5 | G13: 0.82 | H13: 16.5 | I13: 0.84 | J13: 0.097 | K13: 0.049 | L13: 0.048
A14: EWJ | B14: Japan iShares MSCI ETF | C14: 88.13 | D14: 0.2527 | E14: ETF | F14: 89.5 | G14: 1.6 | H14: 86.5 | I14: 1.45 | J14: 0.035 | K14: 0.016 | L14: 0.018
A15: EWZ | B15: Brazil iShares MSCI ETF | C15: 41.33 | D15: 0.3253 | E15: ETF | F15: 42 | G15: 1.01 | H15: 40.5 | I15: 0.89 | J15: 0.046 | K15: 0.022 | L15: 0.024
A16: IAU | B16: Gold Trust iShares | C16: 89.56 | D16: 0.2729 | E16: ETF | F16: 91 | G16: 1.95 | H16: 88 | I16: 1.7 | J16: 0.041 | K16: 0.019 | L16: 0.022
... A24: RNG | B24: Ringcentral Inc | C24: 33.49 | D24: 0.7579 | E24: Technology | F24: 34 | G24: 2.05 | H24: 32 | I24: 1.8 | J24: 0.115 | K24: 0.054 | L24: 0.061

Sheet Bull Strangle - Deviations
A1: Bull Strangle — Newsletter vs OptionSamurai Deviations | April 13, 2026 Entry / May 8, 2026 Expiration
A2: Compares Newsletter (Friday close) vs OptionSamurai live data. Green = match/better, Red = deviation worth noting.
A3: Legend: Price Δ = 0 is expected (both use same Friday close). Strike Δ = OS live vs NL static — non-zero is expected (OS updates intraday). Cred Δ = OS total credit minus NL total credit.
A4: Identifier | C4: Stock Price | G4: Call Strike | J4: Put Strike | M4: Bull Strangle Return | O4: Option Premiums | T4: Earnings | U4: OS Filter
A5: Symbol | B5: Sector | C5: NL Last Price | D5: OS Last Price | E5: Price Δ ($) | F5: Price Δ (%) | G5: NL Call Strike | H5: OS Call Strike | I5: Call Stk Δ ($) | J5: NL Put Strike | K5: OS Put Strike | L5: Put Stk Δ ($) | M5: NL Bull Return | N5: OS Bull Return | O5: NL Call Bid | P5: OS Call Bid | Q5: NL Put Bid | R5: OS Put Bid | S5: Cred Δ ($) | T5: Next Earnings | U5: TRADE? (OS)
A6: PSKY | B6: Communication Services | C6: 10.62 | D6: ='Bull Strangle - Option Samurai'!B6 -> 11.61 | E6: =IF(ISNUMBER(D6),D6-C6,"N/A") -> 0.99 | F6: =IF(AND(ISNUMBER(D6),C6<>0),(D6-C6)/C6,"N/A") -> 0.093220339 | G6: 11 | H6: ='Bull Strangle - Option Samurai'!J6 -> 12 | I6: =IF(ISNUMBER(H6),H6-G6,"N/A") -> 1 | J6: 10 | K6: ='Bull Strangle - Option Samurai'!L6 -> 11.5 | L6: =IF(ISNUMBER(K6),K6-J6,"N/A") -> 1.5 | M6: 0.1337 | N6: ='Bull Strangle - Option Samurai'!O6 -> 0.080103359 | O6: 0.42 | P6: ='Bull Strangle - Option Samurai'!K6 -> 0.38 | Q6: 1 | R6: ='Bull Strangle - Option Samurai'!M6 -> 0.55 | S6: =IF(AND(ISNUMBER(P6),ISNUMBER(R6)),(P6+R6)-(O6+Q6),"N/A") -> -0.49 | T6: ='Bull Strangle - Option Samurai'!V6 -> 2026-05-04 | U6: ='Bull Strangle - Option Samurai'!AD6 -> 🚫 NO
A7: DECK | B7: Consumer Discretionary | C7: 107.86 | D7: ='Bull Strangle - Option Samurai'!B7 -> 110.17 | E7: =IF(ISNUMBER(D7),D7-C7,"N/A") -> 2.31 | F7: =IF(AND(ISNUMBER(D7),C7<>0),(D7-C7)/C7,"N/A") -> 0.021416651 | G7: 110 | H7: ='Bull Strangle - Option Samurai'!J7 -> 112 | I7: =IF(ISNUMBER(H7),H7-G7,"N/A") -> 2 | J7: 106 | K7: ='Bull Strangle - Option Samurai'!L7 -> 109 | L7: =IF(ISNUMBER(K7),K7-J7,"N/A") -> 3 | M7: 0.0593 | N7: ='Bull Strangle - Option Samurai'!O7 -> 0.050376691 | O7: 3.4 | P7: ='Bull Strangle - Option Samurai'!K7 -> 2.7 | Q7: 3 | R7: ='Bull Strangle - Option Samurai'!M7 -> 2.85 | S7: =IF(AND(ISNUMBER(P7),ISNUMBER(R7)),(P7+R7)-(O7+Q7),"N/A") -> -0.85 | T7: ='Bull Strangle - Option Samurai'!V7 -> 2026-05-21 | U7: ='Bull Strangle - Option Samurai'!AD7 -> 🚫 NO
A8: GME | B8: Consumer Discretionary | C8: 23.22 | D8: ='Bull Strangle - Option Samurai'!B8 -> 24.46 | E8: =IF(ISNUMBER(D8),D8-C8,"N/A") -> 1.24 | F8: =IF(AND(ISNUMBER(D8),C8<>0),(D8-C8)/C8,"N/A") -> 0.053402239 | G8: 24 | H8: ='Bull Strangle - Option Samurai'!J8 -> 25 | I8: =IF(ISNUMBER(H8),H8-G8,"N/A") -> 1 | J8: 22.5 | K8: ='Bull Strangle - Option Samurai'!L8 -> 24 | L8: =IF(ISNUMBER(K8),K8-J8,"N/A") -> 1.5 | M8: 0.034 | N8: ='Bull Strangle - Option Samurai'!O8 -> 0.041291905 | O8: 0.35 | P8: ='Bull Strangle - Option Samurai'!K8 -> 0.64 | Q8: 0.44 | R8: ='Bull Strangle - Option Samurai'!M8 -> 0.37 | S8: =IF(AND(ISNUMBER(P8),ISNUMBER(R8)),(P8+R8)-(O8+Q8),"N/A") -> 0.22 | T8: ='Bull Strangle - Option Samurai'!V8 -> 2026-06-09 | U8: ='Bull Strangle - Option Samurai'!AD8 -> ✅ YES
A9: JD | B9: Consumer Discretionary | C9: 28.93 | D9: ='Bull Strangle - Option Samurai'!B9 -> 30.52 | E9: =IF(ISNUMBER(D9),D9-C9,"N/A") -> 1.59 | F9: =IF(AND(ISNUMBER(D9),C9<>0),(D9-C9)/C9,"N/A") -> 0.054960249 | G9: 30 | H9: ='Bull Strangle - Option Samurai'!J9 -> 31 | I9: =IF(ISNUMBER(H9),H9-G9,"N/A") -> 1 | J9: 28 | K9: ='Bull Strangle - Option Samurai'!L9 -> 30 | L9: =IF(ISNUMBER(K9),K9-J9,"N/A") -> 2 | M9: 0.0484 | N9: ='Bull Strangle - Option Samurai'!O9 -> 0.042922674 | O9: 0.73 | P9: ='Bull Strangle - Option Samurai'!K9 -> 0.65 | Q9: 0.67 | R9: ='Bull Strangle - Option Samurai'!M9 -> 0.66 | S9: =IF(AND(ISNUMBER(P9),ISNUMBER(R9)),(P9+R9)-(O9+Q9),"N/A") -> -0.09 | T9: ='Bull Strangle - Option Samurai'!V9 -> 2026-05-12 | U9: ='Bull Strangle - Option Samurai'!AD9 -> ✅ YES
